Workbook
Name Activities_English_Choices: Variables!$FZ$2:$FZ$10
Name Activities_English_Text: INDEX(Activities_English_Choices, MATCH(TRUE, INDEX(Activities_French_Choices=#REF!, 0), 0), 1)
Name Activities_French_Choices: Variables!$GA$2:$GA$10
Name Activities_French_Text: INDEX(Activities_French_Choices, MATCH(TRUE, INDEX(Activities_English_Choices='CTO Inspection English'!XFD1, 0), 0), 1)
Name Currently_Registered: Variables!$EQ$2:$EQ$3
Name Deficiency_English_Choices: Variables!$EW$2:$FG$7
Name Deficiency_English_List: OFFSET(Deficiency_English_List_Choices, 0,0,COUNTA(Deficiency_English_List_Choices),1)
Name Deficiency_English_List_Choices: INDEX(Deficiency_English_Choices, 0, MATCH('IID English'!XFC1,Inspection_Regulation_English_Choices, 0))
Name Deficiency_English_Text: INDEX(Line_Deficiency_English_Choices, MATCH(TRUE, INDEX(Line_Deficiency_French_Choices='IID English'!#REF!, 0), 0), 1)
Name Deficiency_French_Choices: Variables!$FI$2:$FS$7
Name Deficiency_French_List: OFFSET(Deficiency_French_List_Choices, 0, 0,COUNTA(Deficiency_French_List_Choices), 1)
Name Deficiency_French_List_Choices: INDEX(Deficiency_French_Choices, MATCH(TRUE, INDEX(Inspection_Regulation_French_Choices=#REF!, 0), 0), 1)
Name Deficiency_French_Text: INDEX(Line_Deficiency_French_Choices, MATCH(TRUE, INDEX(Line_Deficiency_English_Choices='IID English'!XFD1, 0), 0), 1)
Name Establishment_Name_Choices: Variables!$F$2:$F$113
Name Inspection_Outcome_English_Choices: Variables!$FV$2:$FV$5
Name Inspection_Outcome_English_Text: INDEX(Inspection_Outcome_English_Choices, MATCH(TRUE, INDEX(Inspection_Outcome_French_Choices=#REF!, 0), 0), 1)
Name Inspection_Outcome_French_Choices: Variables!$FW$2:$FW$5
Name Inspection_Outcome_French_Text: INDEX(Inspection_Outcome_French_Choices, MATCH(TRUE, INDEX(Inspection_Outcome_English_Choices=#REF!, 0), 0), 1)
Name Inspection_Regulation_English_Choices: Variables!$EU$2:$EU$12
Name Inspection_Regulation_English_Text: INDEX(Inspection_Regulation_English_Choices, MATCH(TRUE, INDEX(Inspection_Regulation_French_Choices=#REF!, 0), 0), 1)
Name Inspection_Regulation_French_Choices: Variables!$EV$2:$EV$12
Name Inspection_Regulation_French_Text: INDEX(Inspection_Regulation_French_Choices, MATCH(TRUE, INDEX(Inspection_Regulation_English_Choices='IID English'!XFD1, 0), 0), 1)
Name Inspection_Type_English_Choices: Variables!$D$2:$D$4
Name Inspection_Type_FR: Variables!$E$2:$E$4
Name Inspection_Type_French_Choices: Variables!$E$2:$E$4
Name Line_Deficiency_English_Choices: Variables!$FT$2:$FT$24
Name Line_Deficiency_French_Choices: Variables!$FU$2:$FU$24
Name Line_English_Choices: Variables!$EO$2:$EO$157
Name Line_French_Choices: Variables!$EP$2:$EP$157
Name Measure_Taken_English_Choices: Variables!$FX$2:$FX$18
Name Measure_Taken_English_Text: INDEX(Measure_Taken_English_Choices, MATCH(TRUE, INDEX(Measure_Taken_French_Choices=#REF!, 0), 0), 1)
Name Measure_Taken_French_Choices: Variables!$FY$2:$FY$18
Name Measure_Taken_French_Text: INDEX(Measure_Taken_French_Choices, MATCH(TRUE, INDEX(Measure_Taken_English_Choices=#REF!, 0), 0), 1)
Name Observation_English_Choices: Variables!$L$2:$BY$14
Name Observation_English_List: OFFSET(Observation_English_List_Choices, 0,0,COUNTA(Observation_English_List_Choices),1)
Name Observation_English_List_Choices: INDEX(Observation_English_Choices, 0, MATCH(#REF!, Regulation_English_Choices, 0))
Name Observation_English_Text: INDEX(Line_English_Choices, MATCH(TRUE, INDEX(Line_French_Choices=#REF!, 0), 0), 1)
Name Observation_French_Choices: Variables!$CA$2:$EN$14
Name Observation_French_List: OFFSET(Observation_French_List_Choices, 0,0,COUNTA(Observation_French_List_Choices),1)
Name Observation_French_List_Choices: INDEX(Observation_French_Choices, 0, MATCH(#REF!, Regulation_French_Choices, 0))
Name Observation_French_Text: INDEX(Line_French_Choices, MATCH(TRUE, INDEX(Line_English_Choices=#REF!, 0), 0), 1)
Name Phase_of_Trial_Choices: Variables!$C$2:$C$11
Name Rating_English_Choices: Variables!$G$2:$G$4
Name Rating_French_Choices: Variables!$H$2:$H$4
Name Regional_Site_Inspected_English_Choices: Variables!$DF$2:$DF$7
Name Regional_Site_Inspected_French_Choices: Variables!$DG$2:$DG$7
Name Regulation_English_Choices: Variables!$K$2:$K$67
Name Regulation_English_Text: INDEX(Regulation_English_Choices, MATCH(TRUE, INDEX(Regulation_French_Choices=#REF!, 0), 0), 1)
Name Regulation_French_Choices: Variables!$BZ$2:$BZ$67
Name Regulation_French_Text: INDEX(Regulation_French_Choices, MATCH(TRUE, INDEX(Regulation_English_Choices=#REF!, 0), 0), 1)

Sheet CTO Inspection English
A1: Reference Number | B1: Establishment Name | C1: Currently Registered | D1: Registration Number | E1: Inspection Type (FR) | F1: Inspection Type (EN) | G1: Inspection Rating | H1: Inspection Start Date (YYYY-MM-DD) | I1: Inspection End Date (YYYY-MM-DD) | J1: Street | K1: City | L1: Province | M1: Country | N1: Postal Code | O1: Activities (EN) | P1: Activities (FR)
A2: FD6FDCC7 | B2: Alberta Health Services - Living Donor Services (Renal) | C2: Y | D2: 100054 | E2: Inspection régulière | F2: Regular Inspection | G2: Inspection in progress | H2: 42884 | I2: 42888 | J2: Rm. 9423, 11402 University Ave. | K2: Edmonton | L2: AB | M2: Canada | N2: T6G 2J3 | O2: Processing, Distribution, Storage | P2: =IF(ISBLANK(O2), "", Activities_French_Text) -> Traitement, Distribution, Conservation
P3: =IF(ISBLANK(O3), "", Activities_French_Text)
P4: =IF(ISBLANK(O4), "", Activities_French_Text)
P5: =IF(ISBLANK(O5), "", Activities_French_Text)
P6: =IF(ISBLANK(O6), "", Activities_French_Text)
P7: =IF(ISBLANK(O7), "", Activities_French_Text)
P8: =IF(ISBLANK(O8), "", Activities_French_Text)
P9: =IF(ISBLANK(O9), "", Activities_French_Text)
P10: =IF(ISBLANK(O10), "", Activities_French_Text)
P11: =IF(ISBLANK(O11), "", Activities_French_Text)
P12: =IF(ISBLANK(O12), "", Activities_French_Text)
P13: =IF(ISBLANK(O13), "", Activities_French_Text)

Sheet IID English
A1: Reference Number | B1: Establishment Name | C1: Inspection Type (FR) | D1: Inspection Type (EN) | E1: Inspection Start Date | F1: Inspection End Date | G1: Observation Number | H1: Line Number | I1: Regulation (EN) | J1: Regulation (FR) | K1: Deficiency(EN) | L1: Deficiency(FR)
A2: =IF(ISBLANK('CTO Inspection English'!A2), "", 'CTO Inspection English'!A2) -> FD6FDCC7 | B2: =IF(ISBLANK('CTO Inspection English'!B2), "", 'CTO Inspection English'!B2) -> Alberta Health Services - Living Donor Services (Renal) | C2: =IF(ISBLANK('CTO Inspection English'!E2), "", 'CTO Inspection English'!E2) -> Inspection régulière | D2: =IF(ISBLANK('CTO Inspection English'!F2), "", 'CTO Inspection English'!F2) -> Regular Inspection | E2: =IF(ISBLANK('CTO Inspection English'!H2), "", 'CTO Inspection English'!H2) -> 42884 | F2: =IF(ISBLANK('CTO Inspection English'!I2), "", 'CTO Inspection English'!I2) -> 42888 | G2: 1 | H2: 1 | I2: 55-63 - Records | J2: =IF(ISBLANK(I2), "", Inspection_Regulation_French_Text) -> 55 à 63 - Dossiers | K2: Deficiencies were noted in the establishment’s records. | L2: =IF(ISBLANK(K2), "", Deficiency_French_Text) -> Des lacunes ont été notées concernant les dossiers de l’établissement.
A3: =IF(ISBLANK(G3), "",A2) -> FD6FDCC7 | B3: =IF(ISBLANK(G3), "", B2) -> Alberta Health Services - Living Donor Services (Renal) | C3: =IF(ISBLANK(G3), "", C2) -> Inspection régulière | D3: =IF(ISBLANK(G3), "", D2) -> Regular Inspection | E3: =IF(ISBLANK(G3), "", E2) -> 42884 | F3: =IF(ISBLANK(G3), "", F2) -> 42888 | G3: 2 | H3: 1 | I3: 70-76 - Quality Assurance System | J3: =IF(ISBLANK(I3), "", Inspection_Regulation_French_Text) -> 70 à 76 - Système d’assurance de la qualité | K3: Deficiencies were noted with standard operating procedures or audits. | L3: =IF(ISBLANK(K3), "", Deficiency_French_Text) -> Des lacunes ont été notées concernant les procédures d’opération normalisées ou les vérifications.
A4: =IF(ISBLANK(G4), "",A3) | B4: =IF(ISBLANK(G4), "", B3) | C4: =IF(ISBLANK(G4), "", C3) | D4: =IF(ISBLANK(G4), "", D3) | E4: =IF(ISBLANK(G4), "", E3) | F4: =IF(ISBLANK(G4), "", F3) | J4: =IF(ISBLANK(I4), "", Inspection_Regulation_French_Text) | L4: =IF(ISBLANK(K4), "", Deficiency_French_Text)
A5: =IF(ISBLANK(G5), "",A4) | B5: =IF(ISBLANK(G5), "", B4) | C5: =IF(ISBLANK(G5), "", C4) | D5: =IF(ISBLANK(G5), "", D4) | E5: =IF(ISBLANK(G5), "", E4) | F5: =IF(ISBLANK(G5), "", F4) | J5: =IF(ISBLANK(I5), "", Inspection_Regulation_French_Text) | L5: =IF(ISBLANK(K5), "", Deficiency_French_Text)
A6: =IF(ISBLANK(G6), "",A5) | B6: =IF(ISBLANK(G6), "", B5) | C6: =IF(ISBLANK(G6), "", C5) | D6: =IF(ISBLANK(G6), "", D5) | E6: =IF(ISBLANK(G6), "", E5) | F6: =IF(ISBLANK(G6), "", F5) | J6: =IF(ISBLANK(I6), "", Inspection_Regulation_French_Text) | L6: =IF(ISBLANK(K6), "", Deficiency_French_Text)
A7: =IF(ISBLANK(G7), "",A6) | B7: =IF(ISBLANK(G7), "", B6) | C7: =IF(ISBLANK(G7), "", C6) | D7: =IF(ISBLANK(G7), "", D6) | E7: =IF(ISBLANK(G7), "", E6) | F7: =IF(ISBLANK(G7), "", F6) | J7: =IF(ISBLANK(I7), "", Inspection_Regulation_French_Text) | L7: =IF(ISBLANK(K7), "", Deficiency_French_Text)
A8: =IF(ISBLANK(G8), "",A7) | B8: =IF(ISBLANK(G8), "", B7) | C8: =IF(ISBLANK(G8), "", C7) | D8: =IF(ISBLANK(G8), "", D7) | E8: =IF(ISBLANK(G8), "", E7) | F8: =IF(ISBLANK(G8), "", F7) | J8: =IF(ISBLANK(I8), "", Inspection_Regulation_French_Text) | L8: =IF(ISBLANK(K8), "", Deficiency_French_Text)
A9: =IF(ISBLANK(G9), "",A8) | B9: =IF(ISBLANK(G9), "", B8) | C9: =IF(ISBLANK(G9), "", C8) | D9: =IF(ISBLANK(G9), "", D8) | E9: =IF(ISBLANK(G9), "", E8) | F9: =IF(ISBLANK(G9), "", F8) | J9: =IF(ISBLANK(I9), "", Inspection_Regulation_French_Text) | L9: =IF(ISBLANK(K9), "", Deficiency_French_Text)
A10: =IF(ISBLANK(G10), "",A9) | B10: =IF(ISBLANK(G10), "", B9) | C10: =IF(ISBLANK(G10), "", C9) | D10: =IF(ISBLANK(G10), "", D9) | E10: =IF(ISBLANK(G10), "", E9) | F10: =IF(ISBLANK(G10), "", F9) | J10: =IF(ISBLANK(I10), "", Inspection_Regulation_French_Text) | L10: =IF(ISBLANK(K10), "", Deficiency_French_Text)
A11: =IF(ISBLANK(G11), "",A10) | B11: =IF(ISBLANK(G11), "", B10) | C11: =IF(ISBLANK(G11), "", C10) | D11: =IF(ISBLANK(G11), "", D10) | E11: =IF(ISBLANK(G11), "", E10) | F11: =IF(ISBLANK(G11), "", F10) | J11: =IF(ISBLANK(I11), "", Inspection_Regulation_French_Text) | L11: =IF(ISBLANK(K11), "", Deficiency_French_Text)
A12: =IF(ISBLANK(G12), "",A11) | B12: =IF(ISBLANK(G12), "", B11) | C12: =IF(ISBLANK(G12), "", C11) | D12: =IF(ISBLANK(G12), "", D11) | E12: =IF(ISBLANK(G12), "", E11) | F12: =IF(ISBLANK(G12), "", F11) | J12: =IF(ISBLANK(I12), "", Inspection_Regulation_French_Text) | L12: =IF(ISBLANK(K12), "", Deficiency_French_Text)
A13: =IF(ISBLANK(G13), "",A12) | B13: =IF(ISBLANK(G13), "", B12) | C13: =IF(ISBLANK(G13), "", C12) | D13: =IF(ISBLANK(G13), "", D12) | E13: =IF(ISBLANK(G13), "", E12) | F13: =IF(ISBLANK(G13), "", F12) | J13: =IF(ISBLANK(I13), "", Inspection_Regulation_French_Text) | L13: =IF(ISBLANK(K13), "", Deficiency_French_Text)
A14: =IF(ISBLANK(G14), "",A13) | B14: =IF(ISBLANK(G14), "", B13) | C14: =IF(ISBLANK(G14), "", C13) | D14: =IF(ISBLANK(G14), "", D13) | E14: =IF(ISBLANK(G14), "", E13) | F14: =IF(ISBLANK(G14), "", F13) | J14: =IF(ISBLANK(I14), "", Inspection_Regulation_French_Text)
A15: =IF(ISBLANK(G15), "",A14) | B15: =IF(ISBLANK(G15), "", B14) | C15: =IF(ISBLANK(G15), "", C14) | D15: =IF(ISBLANK(G15), "", D14) | E15: =IF(ISBLANK(G15), "", E14) | F15: =IF(ISBLANK(G15), "", F14) | J15: =IF(ISBLANK(I15), "", Inspection_Regulation_French_Text)
A16: =IF(ISBLANK(G16), "",A15) | B16: =IF(ISBLANK(G16), "", B15) | C16: =IF(ISBLANK(G16), "", C15) | D16: =IF(ISBLANK(G16), "", D15) | E16: =IF(ISBLANK(G16), "", E15) | F16: =IF(ISBLANK(G16), "", F15) | J16: =IF(ISBLANK(I16), "", Inspection_Regulation_French_Text)
A17: =IF(ISBLANK(G17), "",A16) | B17: =IF(ISBLANK(G17), "", B16) | C17: =IF(ISBLANK(G17), "", C16) | D17: =IF(ISBLANK(G17), "", D16) | E17: =IF(ISBLANK(G17), "", E16) | F17: =IF(ISBLANK(G17), "", F16) | J17: =IF(ISBLANK(I17), "", Inspection_Regulation_French_Text)
A18: =IF(ISBLANK(G18), "",A17) | B18: =IF(ISBLANK(G18), "", B17) | C18: =IF(ISBLANK(G18), "", C17) | D18: =IF(ISBLANK(G18), "", D17) | E18: =IF(ISBLANK(G18), "", E17) | F18: =IF(ISBLANK(G18), "", F17) | J18: =IF(ISBLANK(I18), "", Inspection_Regulation_French_Text)
A19: =IF(ISBLANK(G19), "",A18) | B19: =IF(ISBLANK(G19), "", B18) | C19: =IF(ISBLANK(G19), "", C18) | D19: =IF(ISBLANK(G19), "", D18) | E19: =IF(ISBLANK(G19), "", E18) | F19: =IF(ISBLANK(G19), "", F18) | J19: =IF(ISBLANK(I19), "", Inspection_Regulation_French_Text)
A20: =IF(ISBLANK(G20), "",A19) | B20: =IF(ISBLANK(G20), "", B19) | C20: =IF(ISBLANK(G20), "", C19) | D20: =IF(ISBLANK(G20), "", D19) | E20: =IF(ISBLANK(G20), "", E19) | F20: =IF(ISBLANK(G20), "", F19) | J20: =IF(ISBLANK(I20), "", Inspection_Regulation_French_Text)
A21: =IF(ISBLANK(G21), "",A20) | B21: =IF(ISBLANK(G21), "", B20) | C21: =IF(ISBLANK(G21), "", C20) | D21: =IF(ISBLANK(G21), "", D20) | E21: =IF(ISBLANK(G21), "", E20) | F21: =IF(ISBLANK(G21), "", F20) | J21: =IF(ISBLANK(I21), "", Inspection_Regulation_French_Text)
A22: =IF(ISBLANK(G22), "",A21) | B22: =IF(ISBLANK(G22), "", B21) | C22: =IF(ISBLANK(G22), "", C21) | D22: =IF(ISBLANK(G22), "", D21) | E22: =IF(ISBLANK(G22), "", E21) | F22: =IF(ISBLANK(G22), "", F21) | J22: =IF(ISBLANK(I22), "", Inspection_Regulation_French_Text)
A23: =IF(ISBLANK(G23), "",A22) | B23: =IF(ISBLANK(G23), "", B22) | C23: =IF(ISBLANK(G23), "", C22) | D23: =IF(ISBLANK(G23), "", D22) | E23: =IF(ISBLANK(G23), "", E22) | F23: =IF(ISBLANK(G23), "", F22) | J23: =IF(ISBLANK(I23), "", Inspection_Regulation_French_Text)
A24: =IF(ISBLANK(G24), "",A23) | B24: =IF(ISBLANK(G24), "", B23) | C24: =IF(ISBLANK(G24), "", C23) | D24: =IF(ISBLANK(G24), "", D23) | E24: =IF(ISBLANK(G24), "", E23) | F24: =IF(ISBLANK(G24), "", F23) | J24: =IF(ISBLANK(I24), "", Inspection_Regulation_French_Text)
A25: =IF(ISBLANK(G25), "",A24) | B25: =IF(ISBLANK(G25), "", B24) | C25: =IF(ISBLANK(G25), "", C24) | D25: =IF(ISBLANK(G25), "", D24) | E25: =IF(ISBLANK(G25), "", E24) | F25: =IF(ISBLANK(G25), "", F24) | J25: =IF(ISBLANK(I25), "", Inspection_Regulation_French_Text)
... A41: =IF(ISBLANK(G41), "",A40) | B41: =IF(ISBLANK(G41), "", B40) | C41: =IF(ISBLANK(G41), "", C40) | D41: =IF(ISBLANK(G41), "", D40) | E41: =IF(ISBLANK(G41), "", E40) | F41: =IF(ISBLANK(G41), "", F40) | J41: =IF(ISBLANK(I41), "", Inspection_Regulation_French_Text)
A42: =IF(ISBLANK(I42), "", A41) | B42: =IF(ISBLANK(G42), "", B41) | C42: =IF(ISBLANK(G42), "", C41) | D42: =IF(ISBLANK(G42), "", D41) | E42: =IF(ISBLANK(G42), "", E41) | F42: =IF(ISBLANK(G42), "", F41) | J42: =IF(ISBLANK(I42), "", Inspection_Regulation_French_Text)
A43: =IF(ISBLANK(I43), "", A42) | B43: =IF(ISBLANK(G43), "", B42) | C43: =IF(ISBLANK(G43), "", C42) | D43: =IF(ISBLANK(G43), "", D42) | E43: =IF(ISBLANK(G43), "", E42) | F43: =IF(ISBLANK(G43), "", F42) | J43: =IF(ISBLANK(I43), "", Inspection_Regulation_French_Text)
A44: =IF(ISBLANK(I44), "", A43) | B44: =IF(ISBLANK(G44), "", B43) | C44: =IF(ISBLANK(G44), "", C43) | D44: =IF(ISBLANK(G44), "", D43) | E44: =IF(ISBLANK(G44), "", E43) | F44: =IF(ISBLANK(G44), "", F43) | J44: =IF(ISBLANK(I44), "", Inspection_Regulation_French_Text)
A45: =IF(ISBLANK(I45), "", A44) | B45: =IF(ISBLANK(G45), "", B44) | C45: =IF(ISBLANK(G45), "", C44) | D45: =IF(ISBLANK(G45), "", D44) | E45: =IF(ISBLANK(G45), "", E44) | F45: =IF(ISBLANK(G45), "", F44) | J45: =IF(ISBLANK(I45), "", Inspection_Regulation_French_Text)
A46: =IF(ISBLANK(I46), "", A45) | B46: =IF(ISBLANK(G46), "", B45) | C46: =IF(ISBLANK(G46), "", C45) | D46: =IF(ISBLANK(G46), "", D45) | E46: =IF(ISBLANK(G46), "", E45) | F46: =IF(ISBLANK(G46), "", F45) | J46: =IF(ISBLANK(I46), "", Inspection_Regulation_French_Text)
A47: =IF(ISBLANK(I47), "", A46) | B47: =IF(ISBLANK(G47), "", B46) | C47: =IF(ISBLANK(G47), "", C46) | D47: =IF(ISBLANK(G47), "", D46) | E47: =IF(ISBLANK(G47), "", E46) | F47: =IF(ISBLANK(G47), "", F46) | J47: =IF(ISBLANK(I47), "", Inspection_Regulation_French_Text)
A48: =IF(ISBLANK(I48), "", A47) | B48: =IF(ISBLANK(G48), "", B47) | C48: =IF(ISBLANK(G48), "", C47) | D48: =IF(ISBLANK(G48), "", D47) | E48: =IF(ISBLANK(G48), "", E47) | F48: =IF(ISBLANK(G48), "", F47) | J48: =IF(ISBLANK(I48), "", Inspection_Regulation_French_Text)
A49: =IF(ISBLANK(I49), "", A48) | B49: =IF(ISBLANK(G49), "", B48) | C49: =IF(ISBLANK(G49), "", C48) | D49: =IF(ISBLANK(G49), "", D48) | E49: =IF(ISBLANK(G49), "", E48) | F49: =IF(ISBLANK(G49), "", F48) | J49: =IF(ISBLANK(I49), "", Inspection_Regulation_French_Text)
A50: =IF(ISBLANK(I50), "", A49) | B50: =IF(ISBLANK(G50), "", B49) | C50: =IF(ISBLANK(G50), "", C49) | D50: =IF(ISBLANK(G50), "", D49) | E50: =IF(ISBLANK(G50), "", E49) | F50: =IF(ISBLANK(G50), "", F49) | J50: =IF(ISBLANK(I50), "", Inspection_Regulation_French_Text)
A51: =IF(ISBLANK(I51), "", A50) | B51: =IF(ISBLANK(G51), "", B50) | C51: =IF(ISBLANK(G51), "", C50) | D51: =IF(ISBLANK(G51), "", D50) | E51: =IF(ISBLANK(G51), "", E50) | F51: =IF(ISBLANK(G51), "", F50) | J51: =IF(ISBLANK(I51), "", Inspection_Regulation_French_Text)
A52: =IF(ISBLANK(I52), "", A51) | B52: =IF(ISBLANK(G52), "", B51) | C52: =IF(ISBLANK(G52), "", C51) | D52: =IF(ISBLANK(G52), "", D51) | E52: =IF(ISBLANK(G52), "", E51) | F52: =IF(ISBLANK(G52), "", F51) | J52: =IF(ISBLANK(I52), "", Inspection_Regulation_French_Text)
A53: =IF(ISBLANK(I53), "", A52) | B53: =IF(ISBLANK(G53), "", B52) | C53: =IF(ISBLANK(G53), "", C52) | D53: =IF(ISBLANK(G53), "", D52) | E53: =IF(ISBLANK(G53), "", E52) | F53: =IF(ISBLANK(G53), "", F52) | J53: =IF(ISBLANK(I53), "", Inspection_Regulation_French_Text)
... A59: =IF(ISBLANK(I59), "", A58) | B59: =IF(ISBLANK(G59), "", B58) | C59: =IF(ISBLANK(G59), "", C58) | D59: =IF(ISBLANK(G59), "", D58) | E59: =IF(ISBLANK(G59), "", E58) | F59: =IF(ISBLANK(G59), "", F58) | J59: =IF(ISBLANK(I59), "", Inspection_Regulation_French_Text)
A60: =IF(ISBLANK(I60), "", A59) | B60: =IF(ISBLANK(G60), "", B59) | C60: =IF(ISBLANK(G60), "", C59) | D60: =IF(ISBLANK(G60), "", D59) | E60: =IF(ISBLANK(G60), "", E59) | F60: =IF(ISBLANK(G60), "", F59) | G60: =IF(ISBLANK(I60),"",IF(G59<>"", IF(ISNUMBER(G59), G59 + 1, 1), "")) | J60: =IF(ISBLANK(I60), "", Inspection_Regulation_French_Text)
...

Sheet Variables
A1: Control Number | B1: Inspection Start Date | C1: Province | D1: Inspection Type (EN) | E1: Inspection Type (FR) | F1: Establishment Name | G1: Rating (EN) | H1: Rating (FR) | I1: Order ID | J1: Sub Order ID | K1: Regulation (EN) | L1: Safety of Human Cells, Tissues and Organs for Transplantation | M1: 4 - Prohibition | N1: 6 - Registration | O1: 13 - Registration | P1: 14 - Registration | Q1: 15 - Source Establishment | R1: 16 - Processing - General | S1: 17 - Processing - General | T1: 18 - Donor Suitability Assessment | U1: 19 - Donor Suitability Assessment | V1: 20 - Donor Suitability Assessment | W1: 21 - Donor Suitability Assessment | X1: 22 - Donor Suitability Assessment | Y1: 23 - Donor Suitability Assessment | Z1: 24 - Retrieval | AA1: 25 - Testing | AB1: 26 - Testing | AC1: 27 - Testing | AD1: 28 - Packaging and labelling | AE1: 29 - Packaging and labelling | AF1: 30 - Packaging and labelling | AG1: 31 - Packaging and labelling | AH1: 32 - Packaging and labelling | AI1: 33 - Packaging and labelling | AJ1: 34 - Quarantine | AK1: 35 - Storage | AL1: 36 - Storage | AM1: 37 - Storage | AN1: 38 - Storage | AO1: 39 - Storage | AP1: 40 - Exceptional Distribution | AQ1: 41 - Exceptional Distribution | AR1: 42 - Exceptional Distribution | AS1: 43 - Errors and Accidents | AT1: 44 - Errors and Accidents | AU1: 45 - Errors and Accidents | AV1: 46 - Errors and Accidents | AW1: 47 - Adverse Reactions | AX1: 48 - Adverse Reactions | AY1: 49 - Adverse Reactions | AZ1: 50 - Investigations and Reporting | BA1: 51 - Investigations and Reporting | BB1: 52 - Investigations and Reporting | BC1: 53 - Investigations and Reporting | BD1: 54 - Investigations and Reporting | BE1: 55 - Records | BF1: 56 - Records | BG1: 57 - Records | BH1: 58 - Records | BI1: 59 - Records | BJ1: 60 - Records | BK1: 61 - Records | BL1: 62 - Records | BM1: 63 - Records | BN1: 64 - Personnel | BO1: 65 - Facilities | BP1: 66 - Equipment and Supplies | BQ1: 67 - Equipment and Supplies | BR1: 68 - Equipment and Supplies | BS1: 69 - Equipment and Supplies | BT1: 71 - Quality Assurance System - General | BU1: 72 - Standard Operating Procedures | BV1: 73 - Standard Operating Procedures | BW1: 74 - Standard Operating Procedures | BX1: 75 - Standard Operating Procedures | BY1: 76 - Standard Operating Procedures | BZ1: Regulation (FR) | CA1: Sécurité des cellules, tissus et organes humains destinés à la transplantation | CB1: 4 - Interdiction | CC1: 6 - Enregistrement | CD1: 13 - Enregistrement | CE1: 14 - Enregistrement | CF1: 15 - Établissement central | CG1: 16 -Traitement - Dispositions générales | CH1: 17 - Traitement - Dispositions générales | CI1: 18 -Évaluation de l’admissibilité du donneur | CJ1: 19 -Évaluation de l’admissibilité du donneur | CK1: 20 -Évaluation de l’admissibilité du donneur | CL1: 21 -Évaluation de l’admissibilité du donneur | CM1: 22 -Évaluation de l’admissibilité du donneur | CN1: 23 -Évaluation de l’admissibilité du donneur | CO1: 24 - Prélèvement | CP1: 25 - Essais | CQ1: 26 - Essais | CR1: 27 - Essais | CS1: 28 - Emballage et étiquetage | CT1: 29 - Emballage et étiquetage | CU1: 30 - Emballage et étiquetage | CV1: 31 - Emballage et étiquetage | CW1: 32 - Emballage et étiquetage | CX1: 33 - Emballage et étiquetage | CY1: 34 - Quarantaine | CZ1: 35 - Conservation | DA1: 36 - Conservation | DB1: 37 - Conservation | DC1: 38 - Conservation | DD1: 39 - Conservation | DE1: 40 - Distribution exceptionnelle | DF1: 41 - Distribution exceptionnelle | DG1: 42 - Distribution exceptionnelle | DH1: 43 - Accidents et manquements | DI1: 44 - Accidents et manquements | DJ1: 45 - Accidents et manquements | DK1: 46 - Accidents et manquements | DL1: 47 - Effets indésirables | DM1: 48 - Effets indésirables | DN1: 49 - Effets indésirables | DO1: 50 - Enquêtes et rapports | DP1: 51 - Enquêtes et rapports | DQ1: 52 - Enquêtes et rapports | DR1: 53 - Enquêtes et rapports | DS1: 54 - Enquêtes et rapports | DT1: 55 - Dossiers | DU1: 56 - Dossiers | DV1: 57 - Dossiers | DW1: 58 - Dossiers | DX1: 59 - Dossiers | DY1: 60 - Dossiers | DZ1: 61 - Dossiers | EA1: 62 - Dossiers | EB1: 63 - Dossiers | EC1: 64 - Personnel | ED1: 65 - Installations | EE1: 66 - Équipement, matériel et produits | EF1: 67 - Équipement, matériel et produits | EG1: 68 - Équipement, matériel et produits | EH1: 69 - Équipement, matériel et produits | EI1: 71 - Système d’assurance de la qualité - Dispositions générales | EJ1: 72 - Procédures d’opération normalisées | EK1: 73 - Procédures d’opération normalisées | EL1: 74 - Procédures d’opération normalisées | EM1: 75 - Procédures d’opération normalisées | EN1: 76 - Procédures d’opération normalisées | EO1: Observation(EN) | EP1: Observation(FR) | EQ1: Licensed (EN) | ER1: Licensed (FR) | EU1: Regulation_Deficiency (EN) | EV1: Regulation_Deficiency (FR) | EW1: Safety of Human Cells, Tissues and Organs for Transplantation | EX1: 4 - Prohibition | EY1: 5-14 - Registration | EZ1: 15 - Source Establishment | FA1: 16-34 - Processing | FB1: 35-39 - Storage | FC1: 40-42 - Exceptional Distribution | FD1: 43-54 - Error, Accident and Adverse Reaction Investigation and Reporting | FE1: 55-63 - Records | FF1: 64-69 - Personnel, Facilities, Equipment and Supplies | FG1: 70-76 - Quality Assurance System | FH1: Regulation_Deficiency (FR) | FI1: Sécurité des cellules, tissus et organes humains destinés à la transplantation | FJ1: 4 - Interdiction | FK1: 5 à 14 - Demande d’enregistrement | FL1: 15 - Établissement central | FM1: 16 à 34 - Traitement | FN1: 35 à 39 - Conservation | FO1: 40 à 42 - Distribution exceptionnelle | FP1: 43 à 54 - Enquêtes et rapports concernant les accidents, manquements et effets indésirables | FQ1: 55 à 63 - Dossiers | FR1: 64 à 69 - Personnel, installations, équipements et produits | FS1: 70 à 76 - Système d’assurance de la qualité | FT1: Deficiency (EN) | FU1: Deficiency (FR) | FV1: InspectionOutcome(EN) | FW1: InspectionOutcome(FR) | FX1: MeasureTaken(EN) | FY1: MeasureTaken(FR) | FZ1: Activites (EN) | GA1: Activities (FR)
A2: 67847 | C2: AB | D2: Regular Inspection | E2: Inspection régulière | F2: Abbott Corporation | G2: C | H2: C | K2: Safety of Human Cells, Tissues and Organs for Transplantation | L2: No deficiencies were noted. | M2: The establishment transplanted cells, tissues or organs that were not processed by a registered establishment. | N2: The establishment’s application for registration did not contain all required information. | O2: The establishment did not notify Health Canada in writing within 30 days of a change in the information on its registration application. | P2: The establishment did not provide the requested information to Health Canada by the required date. | Q2: The establishment did not sufficiently demonstrate its responsibility for assessing the safety of cells, tissues or organs processed by themselves or by another establishment. | R2: The establishment did not have documented evidence to demonstrate that all its activities, processes, and technical procedures would consistently achieve the expected results. | S2: The establishment inappropriately pooled cells, tissues or organs from different donors for one recipient. | T2: The establishment did not collect all required history and information on the donors. | U2: The establishment did not apply plasma dilution algorithms when required. | V2: For tissue donors, the establishment did not assess donors for all factors that could or would exclude them from donating. | W2: For ocular tissue donors, the establishment did not assess donors for all factors that could or would exclude them from donating. | X2: For organ or islet cell donors, the establishment did not collect all required history and information on the donors. | Y2: For lymphohematopoietic cells, the establishment did not collect all required history and information on the donors. | Z2: The establishment did not retrieve tissues within the established timelines. | AA2: The establishment used test kits for transmissible diseases that were not licensed. | AB2: The establishment used test kits for transmissible diseases that were not licensed for donor screening. | AC2: The establishment did not perform bacterial testing. | AD2: The establishment did not ensure the packaging materials were free from damage. | AE2: The label or package insert information was not in English or French. | AF2: Cells were not labelled with all required information. | AG2: Tissues were not labelled with all required information. | AH2: Organs were not labelled with all required information. | AI2: The labels did not include all of the required information. | AJ2: The establishment did not quarantine cells or tissues until it determined the donors were suitable. | AK2: The establishment did not adhere to the maximum storage periods for cells, tissues or organ adjunct vessels. | AL2: The establishment did not store cells, tissues or organs under appropriate environmental conditions. | AM2: The establishment did not ship cells, tissues or organs under appropriate environmental conditions. | AN2: The establishment did not appropriately segregate tissues. | AO2: The establishment did not segregate untested or positive cells, tissues or organs. | AP2: The establishment did not meet the required conditions to release under exceptional distribution. | AQ2: The establishment did not keep a copy of the notices of exceptional distribution. | AR2: The establishment did not provide the transplant establishments with the completed donor suitability documentation when exceptional distribution was used. | AS2: The establishment did not take all required steps when the safety of a cell, tissue or organ may have been compromised by errors or accidents during processing. | AT2: The source establishment did not take all required actions when the safety of a cell, tissue or organ may have been compromised by errors or accidents during processing. | AU2: The source establishment did not advise other establishments when investigations were not needed. | AV2: The establishment did not immediately quarantine all affected cells, tissues and organs, following receipt of error or accident notices. | AW2: The establishment did not take all required actions when unexpected adverse reactions may have occurred. | AX2: The source establishment did not take all required actions when unexpected adverse reactions may have occurred. | AY2: The establishment did not immediately quarantine all affected cells, tissues and organs, following receipt of adverse reaction notices. | AZ2: The establishment did not provide source establishments with information relevant to investigations. | BA2: The source establishment did not provide Health Canada with error or accident reports where required. | BB2: The source establishment did not advise the required establishments of the results of its investigations. | BC2: The source establishment did not advise the required establishments of the results of its investigations. | BD2: The source establishment did not provide Health Canada with the final reports on its investigations. | BE2: The establishment's record were not always accurate, complete, legible and/or indelible. | BF2: The source establishment did not assign a donor identification code to each donor. | BG2: The establishment’s records did not identify the establishment from which it received the cells, tissues or organs. | BH2: The establishment’s records did not include all shipping documents. | BI2: The source establishment did not keep all required records for the cells, tissues and organs it processed. | BJ2: The transplant establishment did not keep all required records for the cells, tissues and organs it transplanted. | BK2: The establishment did not provide the source and/or transplant establishments with all required information to complete their records. | BL2: The establishment did not keep records for the required amount of time. | BM2: The establishment stored records in locations which did not have appropriate environmental conditions. | BN2: The establishment did not have sufficient qualified personnel to carry out its activities. | BO2: The facilities were not constructed and maintained to permit all or some activities to be conducted. | BP2: The equipment cleaning and maintenance was not adequate. | BQ2: The establishment did not use equipment that maintained appropriate environment conditions for the storage of cells, tissues or organs. | BR2: The establishment used processing supplies that were not qualified. | BS2: The establishment used cleaning, maintenance, disinfection or sterilization supplies that could negatively affect the cells, tissues or organs. | BT2: The establishment’s quality assurance system did not comply with the regulatory requirements. | BU2: The establishment did not have standard operating procedures for all its activities. | BV2: The standard operating procedures were not in a standardized format. | BW2: The establishment did not review their standard operating procedures every two years. | BX2: The establishment did not keep records showing that standard operating procedures had been implemented. | BY2: The establishment did not conduct an audit of all regulated activities every two years. | BZ2: Sécurité des cellules, tissus et organes humains destinés à la transplantation | CA2: Aucune lacune n’a été notée. | CB2: L’établissement avait transplanté des cellules, tissus ou organes qui n’avaient pas été traités par un établissement enregistré. | CC2: La demande d’enregistrement ne contenait pas tous les renseignements exigés. | CD2: L’établissement n’avait pas avisé Santé Canada par écrit d’un changement apporté aux renseignements figurant dans sa demande d’enregistrement dans les trente jours suivant ce changement. | CE2: L’établissement n’avait pas les renseignements demandés à Santé Canada dans le délai prescrit. | CF2: L’établissement n’avait pas suffisamment démontré sa responsabilité au sujet de l’évaluation de la sécurité des cellules, tissus ou organes qui ont été traités par lui-même ou par un autre établissement. | CG2: L’établissement ne disposait pas de la documentation permettant de démontrer que toutes les activités et procédures et tous les procédés techniques permettraient d’atteindre de façon constante les résultats anticipés. | CH2: L’établissement avait mis en commun de façon inappropriée des cellules, tissus ou organes provenant de donneurs différents destinés à un seul receveur. | CI2: L’établissement n’avait pas recueilli tous les renseignements et antécédents exigés sur les donneurs. | CJ2: L’établissement n’avait pas appliqué d’algorithmes de dilution plasmatique quand il le fallait. | CK2: L’établissement n’avait pas évalué les donneurs de tissus pour tous les facteurs qui pouvaient ou auraient pu les exclure du don. | CL2: L’établissement n’avait pas évalué les donneurs de tissus oculaires pour tous les facteurs qui pouvaient ou auraient pu les exclure du don. | CM2: L’établissement n’avait pas recueilli tous les renseignements et antécédents des donneurs d’organe ou d’îlots de Langerhans. | CN2: L’établissement n’avait pas recueilli tous les renseignements et antécédents exigés des donneurs de cellules lymphohématopoïétiques. | CO2: L’établissement n’avait pas effectué les prélèvements de tissus dans les délais prescrits. | CP2: L’établissement avait utilisé des trousses d’essais de dépistage des maladies transmissibles non homologuées. | CQ2: L’établissement avait utilisé des trousses d’essais de dépistage des maladies transmissibles non homologuées pour l’évaluation préliminaire de donneurs. | CR2: L’établissement n’avait pas effectué les essais bactériologiques. | CS2: L’établissement ne s’était pas assuré que les matériaux d’emballage n’étaient pas endommagés. | CT2: Les renseignements sur l’étiquette ou l’encart informatif n’étaient ni en français ni en anglais. | CU2: Des cellules n’avaient pas été étiquetées avec tous les renseignements exigés. | CV2: Des tissus n’avaient pas été étiquetés avec tous les renseignements exigés. | CW2: Des organes n’avaient pas été étiquetés avec tous les renseignements exigés. | CX2: Les étiquettes ne comportaient pas tous les renseignements exigés. | CY2: L’établissement n’avait pas mis en quarantaine des cellules ou des tissus jusqu’à ce que les donneurs aient été jugés admissibles. | CZ2: L’établissement n’avait pas respecté les périodes de conservation maximales des cellules, tissus ou vaisseaux prélevés avec un organe. | DA2: L’établissement n’avait pas conservé des cellules, tissus ou organes dans des conditions ambiantes et matérielles appropriées. | DB2: L’établissement n’avait pas expédié des cellules, tissus ou organes dans des conditions ambiantes et matérielles appropriées. | DC2: L’établissement n’avait pas mis des tissus à l’écart de façon appropriée. | DD2: L’établissement n’avait pas mis à l’écart des cellules, tissus ou organes qui n’avaient pas encore fait l’objet d’essais ou dont les résultats des essais s’étaient révélés positifs. | DE2: L’établissement n’avait pas respecté les conditions exigées permettant d’effectuer la distribution exceptionnelle. | DF2: L’établissement n’avait pas versé dans ses dossiers une copie des avis de distribution exceptionnelle. | DG2: L’établissement n’avait pas fourni aux établissements où se faisait la transplantation les évaluations terminées de l’admissibilité du donneur lorsqu’on avait eu recours à la distribution exceptionnelle. | DH2: L’établissement n’avait pas pris toutes les mesures nécessaires lorsque la sécurité des cellules, tissus ou organes avait pu être compromise par des accidents ou des manquements pendant le traitement. | DI2: L’établissement central n’avait pas pris toutes les mesures nécessaires lorsque la sécurité des cellules, tissus ou organes avait pu être compromise par des accidents ou des manquements pendant le traitement. | DJ2: L’établissement central n’avait pas avisé les autres établissements lorsqu’une enquête n’était pas nécessaire. | DK2: L’établissement, après avoir reçu des avis d’accident ou de manquement, n’avait pas immédiatement mis en quarantaine tous les organes, tissus ou cellules en cause. | DL2: L’établissement n’avait pas pris toutes les mesures nécessaires lorsque des effets indésirables imprévus auraient pu se produire. | DM2: L’établissement central n’avait pas pris toutes les mesures nécessaires lorsque des effets indésirables imprévus auraient pu se produire | DN2: L’établissement, après avoir reçu des avis sur des effets indésirables, n’avait pas immédiatement mis en quarantaine tous les organes, tissus et cellules en cause. | DO2: L’établissement n’avait pas fourni aux établissements centraux les renseignements utiles aux enquêtes. | DP2: L’établissement central n’avait pas fourni à Santé Canada les rapports d’accident ou de manquement lorsque requis. | DQ2: L’établissement central n’avait pas avisé les établissements concernés du résultat de ses enquêtes. | DR2: L’établissement central n’avait pas avisé les établissements concernés des résultats de ses enquêtes. | DS2: L’établissement central n’avait pas fourni à Santé Canada les rapports d’enquêtes finaux. | DT2: Le contenu des dossiers de l’établissement n’était pas toujours exact, complet, lisible et/ou indélébile. | DU2: L’établissement central n’avait pas attribué un code d’identification du donneur à chaque donneur. | DV2: Les dossiers de l’établissement ne permettaient pas de déterminer l’établissement duquel provenaient les cellules, les tissus ou les organes. | DW2: Les dossiers de l’établissement ne comprenaient pas tous les documents d’expédition. | DX2: L’établissement central n’avait pas tenu tous les dossiers nécessaires à l’égard des cellules, tissus et organes qu’il traitait. | DY2: L’établissement où se fait la transplantation n’avait pas tenu tous les dossiers nécessaires à l’égard des cellules, tissus et organes qu’il avait transplanté. | DZ2: L’établissement n’avait pas fourni aux établissements centraux et/ou aux établissements où se faisait la transplantation tous les renseignements requis permettant de compléter leurs dossiers. | EA2: L’établissement n’avait pas respecté la période exigée de conservation des dossiers. | EB2: L’établissement avait entreposé ses dossiers dans des lieux où les conditions ambiantes et matérielles étaient appropriées. | EC2: L’établissement n’avait pas le personnel qualifié en nombre suffisant pour exercer ses activités. | ED2: Les installations n’étaient pas construites et entretenues de manière à permettre l’exécution de toutes ou certaines des activités. | EE2: L’équipement de nettoyage et d’entretien était inadéquat. | EF2: L’établissement n’avait pas utilisé l’équipement permettant de maintenir des conditions ambiantes et matérielles appropriées pour la conservation de cellules, tissus ou organes. | EG2: L’établissement avait utilisé du matériel et des produits de traitement non qualifiés. | EH2: L’établissement avait utilisé des produits de nettoyage, d’entretien, de désinfection ou de stérilisation qui auraient pu avoir des effets négatifs sur les cellules, tissus ou organes. | EI2: Le système d’assurance de la qualité de l’établissement n’était pas conforme aux exigences réglementaires. | EJ2: L’établissement n’avait pas de procédures d’opération normalisées pour toutes ses activités. | EK2: Les procédures d’opération normalisées n’étaient pas dans un format type. | EL2: L’établissement n’avait pas révisé ses procédures d’opération normalisées tous les deux ans. | EM2: L’établissement n’avait pas conservé les dossiers démontrant la mise en application des procédures d’opération normalisées. | EN2: L’établissement n’avait pas effectué de vérifications des activités visées par le Règlement tous les deux ans. | EO2: Cells were not labelled with all required information. | EP2: Des cellules n’avaient pas été étiquetées avec tous les renseignements exigés. | EQ2: Y | ER2: Y | EU2: Safety of Human Cells, Tissues and Organs for Transplantation | EV2: Sécurité des cellules, tissus et organes humains destinés à la transplantation | EW2: No deficiencies were noted. | EX2: Deficiencies were noted related to prohibited activities outlined in the Safety of Human Cells, Tissues and Organs for Transplantation Regulations. | EY2: Deficiencies were noted with the establishment’s application for registration. | EZ2: Deficiencies were noted in the source establishment meeting its responsibilities. | FA2: Deficiencies were noted in the general processing of cells, tissues or organs. | FB2: Deficiencies were noted in the storage of cells, tissues or organs. | FC2: Deficiencies were noted in the establishment’s exceptional distribution process. | FD2: Deficiencies were noted in the actions taken when errors or accidents occurred. | FE2: Deficiencies were noted in the establishment’s records. | FF2: Deficiencies were noted in personnel qualifications or training. | FG2: Deficiencies were noted with the quality assurance system | FH2: Sécurité des cellules, tissus et organes humains destinés à la transplantation | FI2: Aucune lacune n’a été notée. | FJ2: Des lacunes ont été notées concernant les activités interdites indiquées dans le Règlement sur la sécurité des cellules, tissus et organes humains destinés à la transplantation. | FK2: Des lacunes ont été notées concernant la demande d’enregistrement de l’établissement. | FL2: Des lacunes ont été notées concernant le respect des responsabilités que doit assumer l’établissement central. | FM2: Des lacunes ont été notées concernant le traitement général des cellules, des tissus ou des organes. | FN2: Des lacunes ont été notées concernant la conservation des cellules, des tissus ou des organes. | FO2: Des lacunes ont été notées concernant le processus de distribution exceptionnelle de l’établissement. | FP2: Des lacunes ont été notées concernant les mesures prises en cas d’accidents ou de manquements. | FQ2: Des lacunes ont été notées concernant les dossiers de l’établissement. | FR2: Des lacunes ont été notées concernant les qualifications ou la formation du personnel. | FS2: Des lacunes ont été notées concernant le système d’assurance de la qualité. | FT2: No deficiencies were noted. | FU2: Aucune lacune n’a été notée. | FV2: The inspection resulted in a compliant rating.The establishment was compliant with the Safety of Human Cells, Tissues and Organs for Transplantation Regulations. | FW2: L'inspection a entraîné l'attribution d'une cote de conformité.L'établissement respectait le Règlement sur la sécurité des cellules, tissus et organes humains destinés à la transplantation. | FX2: We requested corrective actions. | FY2: Nous avons demandé des mesures correctives. | FZ2: Processing, Importation, Distribution, Storage | GA2: Traitement, Importation, Distribution, Conservation
A3: 70412 | C3: BC | D3: Re-Inspection | E3: Réinspection | F3: Abbvie Corporation | G3: NC | H3: NC | K3: 4 - Prohibition | M3: The establishment transplanted cells, tissues or organs that were not determined safe for transplantation. | O3: The establishment did not notify Health Canada in writing within 90 days of stopping activities. | Q3: The establishment did not demonstrate that the cells, tissues or organs were safe for transplantation. | T3: The establishment did not assess donors for all factors that could or would exclude them from donating. | U3: The establishment did not accurately calculate the plasma dilutions. | V3: For tissue donors, the establishment did not use appropriate and effective tests for infectious disease testing. | X3: For organ or islet cell donors, the establishment did not assess donors for all factors that could or would exclude them from donating. | Y3: For lymphohematopoietic cells, the establishment did not perform the required physical exam on the donors. | AA3: For imported lymphohematopoietic cells, the establishment used test kits for transmissible diseases that were not licensed. | AF3: Pancreases were not labelled with all required information. | AJ3: The establishment did not quarantine cells or tissues until it had reviewed the bacterial test results. | AL3: The establishment stored cells, tissues or organs in locations that were accessible to unauthorized persons. | AQ3: The notices of exceptional distribution did not include all required information. | AS3: The importer did not notify source establishments after it was notified of errors or accidents. | AT3: The source establishment did not adequately complete error or accident reports. | AV3: The establishment did not forward copies of error or accident notices to every establishment to whom they distributed cells, tissues and organs. | AW3: The importer did not notify source establishments when it received adverse reactions notices. | AX3: The source establishment did not adequately complete adverse reaction notices. | AY3: The establishment did not forward copies of adverse reaction notices to every establishment to whom they distributed cells, tissues and organs. | BA3: The source establishment did not provide Health Canada with unexpected serious adverse reaction reports where required. | BB3: The establishment did not advise the required establishments of the results of investigations conducted by source establishments. | BC3: The establishment did not advise the required establishments of the results of investigations conducted by source establishments. | BD3: The source establishment did not provide Health Canada with all the required information on its final investigation reports. | BE3: The establishment’s records were not accurate, complete, legible and/or indelible. | BF3: The establishment did not use the donor identification code in its records system. | BG3: The establishment’s records did not identify the establishment to whom it distributed the cells, tissues or organs. | BM3: The establishment stored records in locations that were accessible to unauthorized persons. | BN3: Personnel did not meet all required qualifications with regard to their education, training or experience to perform their respective tasks. | BO3: The facilities were not constructed and maintained to permit efficient cleaning, maintenance and disinfection. | BP3: The equipment was not qualified for its intended purpose. | BR3: The establishment did not store solutions, reagents or other supplies under appropriate environmental conditions. | BU3: The establishment did not follow the standard operating procedures as written. | BV3: The medical or scientific director did not approve the standard operating procedures. | BW3: The establishment did not review their standard operating procedures after a change to the Regulations. | BY3: The audit was conducted by a person who had direct responsibility for the activities being audited. | BZ3: 4 - Interdiction | CB3: L’établissement avait transplanté des cellules, tissus ou organes qui n’avaient pas été jugés sécuritaires aux fins de transplantation. | CD3: L’établissement n’avait pas avisé Santé Canada par écrit dans les quatre-vingt-dix jours suivant la cessation de ses activités. | CF3: L’établissement n’avait pas démontré que les cellules, tissus ou organes étaient sécuritaires aux fins de transplantation. | CI3: L’établissement n’avait pas évalué les donneurs pour tous les facteurs qui pouvaient ou auraient pu les exclure du don. | CJ3: L’établissement n’avait pas calculé correctement les dilutions plasmatiques. | CK3: L’établissement n’avait pas effectué les essais appropriés et efficaces sur les donneurs de tissus aux fins de dépistage des maladies infectieuses. | CM3: L’établissement n’avait pas évalué les donneurs d’organe ou d’îlots de Langerhans pour tous les facteurs qui pouvaient ou auraient pu les exclure du don. | CN3: L’établissement n’avait pas effectué l’examen physique des donneurs de cellules lymphohématopoïétiques tel qu’exigé. | CP3: Dans le cas de cellules lymphohématopoïétiques importées, l’établissement avait utilisé des trousses d’essais de dépistage des maladies transmissibles non homologuées. | CU3: Des pancréas n’avaient pas été étiquetés avec tous les renseignements exigés. | CV3: Des tissus n’avaient pas été étiquetés avec tous les renseignements exigés. | CY3: L’établissement n’avait pas mis en quarantaine des cellules ou des tissus jusqu’à ce qu’il ait examiné les résultats des essais bactériologiques. | DA3: L’établissement avait conservé des cellules, tissus ou organes dans des lieux accessibles aux personnes non autorisées. | DF3: Les avis de distribution exceptionnelle ne comportaient pas tous les renseignements exigés. | DH3: L’importateur n’avait pas avisé les établissements centraux après avoir été informé d’accidents ou manquements. | DI3: L’établissement central n’avait pas complété les rapports d’accident ou de manquement de façon adéquate. | DK3: L’établissement n’avait pas envoyé une copie des avis d’accident ou de manquement à chacun des établissements auquel il avait distribué des cellules, tissus et organes. | DL3: L’importateur n’avait pas avisé les établissements centraux lorsqu’il avait reçu des avis sur des effets indésirables. | DM3: L’établissement central n’avait pas complété les avis sur des effets indésirables de façon adéquate. | DN3: L’établissement n’avait pas envoyé de copie des avis sur des effets indésirables à chacun des établissements auquel il avait distribué des cellules, tissus et organes. | DP3: L’établissement central n’avait pas fourni à Santé Canada les rapports sur les effets indésirables graves imprévus lorsque requis. | DQ3: L’établissement n’avait pas avisé les établissements concernés des résultats des enquêtes menées par les établissements centraux. | DR3: L’établissement n’avait pas avisé les établissements concernés des résultats des enquêtes menées par les établissements centraux. | DS3: L’établissement central n’avait pas fourni à Santé Canada tous les renseignements nécessaires dans ses rapports d’enquête finaux. | DT3: Le contenu des dossiers de l’établissement n’était pas exact, complet, lisible et/ou indélébile. | DU3: L’établissement n’avait pas utilisé le code d’identification du donneur dans son système de dossiers. | DV3: Les dossiers de l’établissement ne permettaient pas de déterminer l’établissement auquel il avait distribué les cellules, les tissus ou les organes. | EB3: L’établissement avait entreposé ses dossiers dans des lieux accessibles à des personnes non autorisées. | EC3: Les membres du personnel ne rencontraient pas toutes les exigences quant à leur qualification de par leurs études, leur formation ou leur expérience pour accomplir leurs tâches respectives. | ED3: Les installations n’étaient pas construites et entretenues de manière à permettre un nettoyage, un entretien et une désinfection efficaces. | EE3: L’équipement n’était pas qualifié en fonction de l’utilisation prévue. | EG3: L’établissement n’avait pas conservé les solutions, les réactifs ou tout autre produit dans des conditions ambiantes et matérielles appropriées. | EJ3: L’établissement n’avait pas suivi les procédures d’opération normalisées telles qu’écrites. | EK3: Le directeur médical ou scientifique n’avait pas approuvé les procédures d’opération normalisées. | EL3: L’établissement n’avait pas révisé ses procédures d’opération normalisées à la suite d’une modification du Règlement. | EN3: La vérification avait été effectuée par une personne directement responsable des activités visées. | EO3: For imported lymphohematopoietic cells, the establishment did not have complete documentation of the donor suitability assessment. | EP3: Dans le cas de cellules lymphohématopoïétiques importées, l’établissement ne disposait pas de la documentation complète concernant l’évaluation de l’admissibilité de donneurs. | EQ3: N | ER3: N | EU3: 4 - Prohibition | EV3: 4 - Interdiction | EY3: Deficiencies were noted in the notification of registration changes to Health Canada. | FA3: Deficiencies were noted in donor suitability assessment. | FD3: Deficiencies were noted in the actions taken when unexpected adverse reactions occurred. | FF3: Deficiencies were noted in the construction or maintenance of the facilities. | FG3: Deficiencies were noted with standard operating procedures or audits. | FH3: 4 - Interdiction | FK3: Des lacunes ont été notées concernant l’avis à Santé Canada au sujet des changements apportés à l’enregistrement. | FM3: Des lacunes ont été notées concernant l’évaluation de l’admissibilité du donneur. | FP3: Des lacunes ont été notées concernant les mesures prises en cas d’effets indésirables imprévus. | FR3: Des lacunes ont été notées concernant la construction ou l’entretien des installations. | FS3: Des lacunes ont été notées concernant les procédures d’opération normalisées ou les vérifications. | FT3: Deficiencies were noted in donor suitability assessment. | FU3: Des lacunes ont été notées concernant l’évaluation de l’admissibilité du donneur. | FV3: The inspection resulted in a non-compliant rating.The establishment was not compliant with the Safety of Human Cells, Tissues and Organs for Transplantation Regulations. | FW3: L'inspection a entraîné l'attribution d'une cote de non-conformité.L'établissement ne respectait pas le Règlement sur la sécurité des cellules, tissus et organes humains destinés à la transplantation. | FX3: We evaluated the establishment’s corrective actions and found them to be satisfactory. | FY3: Nous avons évalué les mesures correctives de l’établissement et les avons considérées satisfaisantes. | FZ3: Processing, Importation, Distribution | GA3: Traitement, Importation, Distribution
